[2024-09-20T12:52:42.940+0000] {local_task_job_runner.py:123} INFO - ::group::Pre task execution logs
[2024-09-20T12:52:42.962+0000] {taskinstance.py:2612} INFO - Dependencies all met for dep_context=non-requeueable deps ti=<TaskInstance: etl_pipeline.run_sink_script scheduled__2024-02-14T00:00:00+00:00 [queued]>
[2024-09-20T12:52:42.975+0000] {taskinstance.py:2612} INFO - Dependencies all met for dep_context=requeueable deps ti=<TaskInstance: etl_pipeline.run_sink_script scheduled__2024-02-14T00:00:00+00:00 [queued]>
[2024-09-20T12:52:42.976+0000] {taskinstance.py:2865} INFO - Starting attempt 2 of 2
[2024-09-20T12:52:43.057+0000] {taskinstance.py:2888} INFO - Executing <Task(BashOperator): run_sink_script> on 2024-02-14 00:00:00+00:00
[2024-09-20T12:52:43.068+0000] {logging_mixin.py:190} WARNING - /home/***/.local/lib/python3.12/site-packages/***/task/task_runner/standard_task_runner.py:70 DeprecationWarning: This process (pid=863) is multi-threaded, use of fork() may lead to deadlocks in the child.
[2024-09-20T12:52:43.068+0000] {standard_task_runner.py:104} INFO - Running: ['***', 'tasks', 'run', 'etl_pipeline', 'run_sink_script', 'scheduled__2024-02-14T00:00:00+00:00', '--job-id', '112', '--raw', '--subdir', 'DAGS_FOLDER/hien_dag.py', '--cfg-path', '/tmp/tmp5hcn3l71']
[2024-09-20T12:52:43.070+0000] {standard_task_runner.py:72} INFO - Started process 870 to run task
[2024-09-20T12:52:43.070+0000] {standard_task_runner.py:105} INFO - Job 112: Subtask run_sink_script
[2024-09-20T12:52:43.134+0000] {task_command.py:467} INFO - Running <TaskInstance: etl_pipeline.run_sink_script scheduled__2024-02-14T00:00:00+00:00 [running]> on host 7554384313c9
[2024-09-20T12:52:43.240+0000] {taskinstance.py:3131} INFO - Exporting env vars: AIRFLOW_CTX_DAG_OWNER='***' AIRFLOW_CTX_DAG_ID='etl_pipeline' AIRFLOW_CTX_TASK_ID='run_sink_script' AIRFLOW_CTX_EXECUTION_DATE='2024-02-14T00:00:00+00:00' AIRFLOW_CTX_TRY_NUMBER='2' AIRFLOW_CTX_DAG_RUN_ID='scheduled__2024-02-14T00:00:00+00:00'
[2024-09-20T12:52:43.241+0000] {taskinstance.py:731} INFO - ::endgroup::
[2024-09-20T12:52:43.264+0000] {subprocess.py:63} INFO - Tmp dir root location: /tmp
[2024-09-20T12:52:43.265+0000] {subprocess.py:75} INFO - Running command: ['/usr/bin/bash', '-c', 'docker-compose exec python-sink python /app/python-scripts/sink.py']
[2024-09-20T12:52:43.283+0000] {subprocess.py:86} INFO - Output:
[2024-09-20T12:52:43.286+0000] {subprocess.py:93} INFO - /usr/bin/bash: line 1: docker-compose: command not found
[2024-09-20T12:52:43.287+0000] {subprocess.py:97} INFO - Command exited with return code 127
[2024-09-20T12:52:43.298+0000] {taskinstance.py:3310} ERROR - Task failed with exception
Traceback (most recent call last):
  File "/home/airflow/.local/lib/python3.12/site-packages/airflow/models/taskinstance.py", line 767, in _execute_task
    result = _execute_callable(context=context, **execute_callable_kwargs)
             ^^^^^^^^^^^^^^^^^^^^^^^^^^^^^^^^^^^^^^^^^^^^^^^^^^^^^^^^^^^^^
  File "/home/airflow/.local/lib/python3.12/site-packages/airflow/models/taskinstance.py", line 733, in _execute_callable
    return ExecutionCallableRunner(
           ^^^^^^^^^^^^^^^^^^^^^^^^
  File "/home/airflow/.local/lib/python3.12/site-packages/airflow/utils/operator_helpers.py", line 252, in run
    return self.func(*args, **kwargs)
           ^^^^^^^^^^^^^^^^^^^^^^^^^^
  File "/home/airflow/.local/lib/python3.12/site-packages/airflow/models/baseoperator.py", line 406, in wrapper
    return func(self, *args, **kwargs)
           ^^^^^^^^^^^^^^^^^^^^^^^^^^^
  File "/home/airflow/.local/lib/python3.12/site-packages/airflow/operators/bash.py", line 249, in execute
    raise AirflowException(
airflow.exceptions.AirflowException: Bash command failed. The command returned a non-zero exit code 127.
[2024-09-20T12:52:43.303+0000] {taskinstance.py:1225} INFO - Marking task as FAILED. dag_id=etl_pipeline, task_id=run_sink_script, run_id=scheduled__2024-02-14T00:00:00+00:00, execution_date=20240214T000000, start_date=20240920T125242, end_date=20240920T125243
[2024-09-20T12:52:43.334+0000] {taskinstance.py:340} INFO - ::group::Post task execution logs
[2024-09-20T12:52:43.335+0000] {standard_task_runner.py:124} ERROR - Failed to execute job 112 for task run_sink_script (Bash command failed. The command returned a non-zero exit code 127.; 870)
Traceback (most recent call last):
  File "/home/airflow/.local/lib/python3.12/site-packages/airflow/task/task_runner/standard_task_runner.py", line 117, in _start_by_fork
    ret = args.func(args, dag=self.dag)
          ^^^^^^^^^^^^^^^^^^^^^^^^^^^^^
  File "/home/airflow/.local/lib/python3.12/site-packages/airflow/cli/cli_config.py", line 49, in command
    return func(*args, **kwargs)
           ^^^^^^^^^^^^^^^^^^^^^
  File "/home/airflow/.local/lib/python3.12/site-packages/airflow/utils/cli.py", line 115, in wrapper
    return f(*args, **kwargs)
           ^^^^^^^^^^^^^^^^^^
  File "/home/airflow/.local/lib/python3.12/site-packages/airflow/cli/commands/task_command.py", line 483, in task_run
    task_return_code = _run_task_by_selected_method(args, _dag, ti)
                       ^^^^^^^^^^^^^^^^^^^^^^^^^^^^^^^^^^^^^^^^^^^^
  File "/home/airflow/.local/lib/python3.12/site-packages/airflow/cli/commands/task_command.py", line 256, in _run_task_by_selected_method
    return _run_raw_task(args, ti)
           ^^^^^^^^^^^^^^^^^^^^^^^
  File "/home/airflow/.local/lib/python3.12/site-packages/airflow/cli/commands/task_command.py", line 341, in _run_raw_task
    return ti._run_raw_task(
           ^^^^^^^^^^^^^^^^^
  File "/home/airflow/.local/lib/python3.12/site-packages/airflow/utils/session.py", line 97, in wrapper
    return func(*args, session=session, **kwargs)
           ^^^^^^^^^^^^^^^^^^^^^^^^^^^^^^^^^^^^^^
  File "/home/airflow/.local/lib/python3.12/site-packages/airflow/models/taskinstance.py", line 3004, in _run_raw_task
    return _run_raw_task(
           ^^^^^^^^^^^^^^
  File "/home/airflow/.local/lib/python3.12/site-packages/airflow/models/taskinstance.py", line 273, in _run_raw_task
    TaskInstance._execute_task_with_callbacks(
  File "/home/airflow/.local/lib/python3.12/site-packages/airflow/models/taskinstance.py", line 3158, in _execute_task_with_callbacks
    result = self._execute_task(context, task_orig)
             ^^^^^^^^^^^^^^^^^^^^^^^^^^^^^^^^^^^^^^
  File "/home/airflow/.local/lib/python3.12/site-packages/airflow/models/taskinstance.py", line 3182, in _execute_task
    return _execute_task(self, context, task_orig)
           ^^^^^^^^^^^^^^^^^^^^^^^^^^^^^^^^^^^^^^^
  File "/home/airflow/.local/lib/python3.12/site-packages/airflow/models/taskinstance.py", line 767, in _execute_task
    result = _execute_callable(context=context, **execute_callable_kwargs)
             ^^^^^^^^^^^^^^^^^^^^^^^^^^^^^^^^^^^^^^^^^^^^^^^^^^^^^^^^^^^^^
  File "/home/airflow/.local/lib/python3.12/site-packages/airflow/models/taskinstance.py", line 733, in _execute_callable
    return ExecutionCallableRunner(
           ^^^^^^^^^^^^^^^^^^^^^^^^
  File "/home/airflow/.local/lib/python3.12/site-packages/airflow/utils/operator_helpers.py", line 252, in run
    return self.func(*args, **kwargs)
           ^^^^^^^^^^^^^^^^^^^^^^^^^^
  File "/home/airflow/.local/lib/python3.12/site-packages/airflow/models/baseoperator.py", line 406, in wrapper
    return func(self, *args, **kwargs)
           ^^^^^^^^^^^^^^^^^^^^^^^^^^^
  File "/home/airflow/.local/lib/python3.12/site-packages/airflow/operators/bash.py", line 249, in execute
    raise AirflowException(
airflow.exceptions.AirflowException: Bash command failed. The command returned a non-zero exit code 127.
[2024-09-20T12:52:43.377+0000] {local_task_job_runner.py:266} INFO - Task exited with return code 1
[2024-09-20T12:52:43.406+0000] {taskinstance.py:3900} INFO - 0 downstream tasks scheduled from follow-on schedule check
[2024-09-20T12:52:43.433+0000] {local_task_job_runner.py:245} INFO - ::endgroup::
